Workbook

Sheet 0_COVER
A1: COMPREHENSIVE FINANCIAL ANALYSIS REPORT
A3: Dunelm Group PLC (FY2019–FY2024) vs Chemring Group PLC (FY2020–FY2025)
A4: All values in £m unless stated otherwise | Prepared using openpyxl | Formula-driven model
A6: Sheet | B6: Contents | C6: Coverage – Dunelm | D6: Coverage – Chemring
A7: Dunelm_Data | B7: Source financial statements – Dunelm | C7: IS, BS, CF, Supplementary | D7: —
A8: Chemring_Data | B8: Source financial statements – Chemring | C8: — | D8: IS, BS, CF, Supplementary
A9: 1_FSA | B9: 1. Financial Statement Analysis | C9: Revenue, GP, EBIT, PAT, EPS, DPS, Assets, Equity, Debt trends | D9: Same metrics
A10: 2_Profitability | B10: 2. Profitability Analysis | C10: Margins, EBITDA, ROE, ROCE, ROA, Cash conversion | D10: Same metrics
A11: 3_Efficiency | B11: 3. Efficiency Analysis | C11: Asset turnover, Inv days, DSO, DPO, CCC, NWC | D11: Same metrics
A12: 4_Liquidity | B12: 4. Liquidity Analysis | C12: Current/quick/cash ratios, WC, FCF/Div cover | D12: Same metrics
A13: 5_Solvency_Risk | B13: 5. Solvency & Risk Analysis | C13: Gearing, leverage, interest cover, DSCR, capex intensity | D13: Same metrics
A14: 6_Market_Investment | B14: 6. Market & Investment Analysis | C14: P/E, P/B, EV/EBITDA, Div yield, TSR, FCF yield | D14: Same metrics
A17: KEY METRICS AT A GLANCE (most recent year: Dunelm FY2024 | Chemring FY2025)
A18: Metric | B18: Dunelm FY2024 | C18: Chemring FY2025 | D18: Commentary
A19: Revenue | B19: £1,706.5m | C19: £497.5m | D19: Dunelm 3.4x larger; different sectors (retail vs defence)
A20: Operating Profit | B20: £213.3m | C20: £73.4m | D20: Chemring EBIT margin 14.8% – highest in period
A21: Profit After Tax | B21: £151.2m | C21: £48.2m | D21: Chemring FY23 PAT distorted by disc. ops
A22: EPS Basic | B22: 74.7p | C22: 19.7p | D22: Both near/at multi-year highs
A23: EBIT Margin | B23: 12.5% | C23: 14.8% | D23: Chemring margin convergence; both improving
A24: ROCE (approx.) | B24: ~36% | C24: ~12% | D24: Dunelm capital-light; Chemring asset-intensive
A25: Net Debt (ex-leases) | B25: £53.6m | C25: £93.9m | D25: Both modest; Chemring rising with investment
A26: Interest Cover | B26: 21.5x | C26: 12.9x | D26: Excellent for both companies
A27: Current Ratio | B27: ~1.0x | C27: ~1.6x | D27: Dunelm low but retail model supports; Chemring solid
A28: DPS | B28: 77.8p | C28: 7.9p | D28: Chemring progressive; Dunelm volatile (specials)
A29: Operating Cash Flow | B29: £232.3m | C29: £91.1m | D29: Both generate strong operational cash
A31: COLOUR KEY & FORMULA CONVENTION
A32: Blue text | B32: Hardcoded input values from source financial statements
A33: Black text | B33: Excel formula — calculated from referenced cells
A34: Red-tinted background | B34: Dunelm data columns in analysis sheets
A35: Green-tinted background | B35: Chemring data columns in analysis sheets
A36: Yellow background | B36: Formula logic column — shows calculation methodology
A37: Dark navy header | B37: Section/category header row
A38: Formula column (B) | B38: Contains written description of each formula for transparency and audit

Sheet Dunelm_Data
A1: DUNELM GROUP PLC — SOURCE DATA
A2: Income Statement, Balance Sheet & Cash Flow | 2019–2024 | Values in £m except EPS (pence)
A3: Line Item | B3: Unit | C3: 2019 | D3: 2020 | E3: 2021 | F3: 2022 | G3: 2023 | H3: 2024
A4: INCOME STATEMENT
A5: Revenue | B5: £m | C5: 1100.4 | D5: 1057.9 | E5: 1336.2 | F5: 1581.4 | G5: 1638.8 | H5: 1706.5
A6: Cost of Sales | B6: £m | C6: -554.8 | D6: -525.5 | E6: -647.3 | F6: -772 | G6: -817.9 | H6: -823.2
A7: Gross Profit | B7: £m | C7: 545.6 | D7: 532.4 | E7: 688.9 | F7: 809.4 | G7: 820.9 | H7: 883.3
A8: Operating Costs | B8: £m | C8: -418.7 | D8: -416.4 | E8: -522.5 | F8: -591.7 | G8: -622.1 | H8: -670
A9: Operating Profit | B9: £m | C9: 126.9 | D9: 116 | E9: 166.4 | F9: 217.7 | G9: 198.8 | H9: 213.3
A10: Financial Income | B10: £m | C10: 0.9 | D10: 0.4 | E10: 0.1 | F10: 1.2 | G10: 1.7 | H10: 2
A11: Financial Expenses | B11: £m | C11: -1.9 | D11: -7.3 | E11: -8.7 | F11: -6.1 | G11: -7.8 | H11: -9.9
A12: Profit Before Tax | B12: £m | C12: 125.9 | D12: 109.1 | E12: 157.8 | F12: 212.8 | G12: 192.7 | H12: 205.4
A13: Taxation | B13: £m | C13: -24.6 | D13: -21.4 | E13: -28.9 | F13: -41.6 | G13: -40.8 | H13: -54.2
A14: Profit After Tax | B14: £m | C14: 101.3 | D14: 87.7 | E14: 128.9 | F14: 171.2 | G14: 151.9 | H14: 151.2
A15: EPS Basic (p) | B15: p | C15: 50.2 | D15: 43.4 | E15: 63.7 | F15: 84.5 | G15: 75.2 | H15: 74.7
A16: EPS Diluted (p) | B16: p | C16: 49.9 | D16: 42.9 | E16: 62.9 | F16: 83.6 | G16: 75 | H16: 74.4
A18: BALANCE SHEET
A19: Total Non-Current Assets | B19: £m | C19: 209.7 | D19: 487.2 | E19: 451.1 | F19: 440.8 | G19: 413.4 | H19: 409.1
A20: of which: Inventories | B20: £m | C20: 157.7 | D20: 118.2 | E20: 172.4 | F20: 223 | G20: 211 | H20: 223
A21: of which: PPE | B21: £m | C21: 180.6 | D21: 175.4 | E21: 162.6 | F21: 173.7 | G21: 169.9 | H21: 173
A22: of which: Right-of-Use | B22: £m | C22: 0 | D22: 283.3 | E22: 262 | F22: 248.5 | G22: 231.3 | H22: 222.9
A23: Total Current Assets | B23: £m | C23: 207.4 | D23: 228.8 | E23: 315.6 | F23: 297.1 | G23: 283.4 | H23: 272.9
A24: of which: Inventories | B24: £m | C24: 157.7 | D24: 118.2 | E24: 172.4 | F24: 223 | G24: 211 | H24: 223
A25: of which: Trade Receivables | B25: £m | C25: 25.6 | D25: 15.6 | E25: 11.8 | F25: 22.9 | G25: 24.3 | H25: 26.2
A26: of which: Cash | B26: £m | C26: 19 | D26: 90 | E26: 128.6 | F26: 30.2 | G26: 46.3 | H26: 23.4
A27: Total Assets | B27: £m | C27: 417.1 | D27: 716 | E27: 766.7 | F27: 737.9 | G27: 696.8 | H27: 682
A28: Total Current Liabilities | B28: £m | C28: -149.8 | D28: -227.8 | E28: -235.9 | F28: -276 | G28: -269.6 | H28: -263.5
A29: of which: Trade Payables | B29: £m | C29: -136.3 | D29: -177.2 | E29: -181.8 | F29: -223.2 | G29: -208.1 | H29: -205
A30: of which: Lease Liab. (C) | B30: £m | C30: 0 | D30: -48 | E30: -49 | F30: -52.8 | G30: -53.4 | H30: -52.1
... A36: of which: Retained Earnings | B36: £m | C36: 134 | D36: 121.3 | E36: 238.7 | F36: 111.2 | G36: 97.5 | H36: 94.8
A38: CASH FLOW STATEMENT
A39: Net Cash from Operations | B39: £m | C39: 174 | D39: 244.1 | E39: 184.2 | F39: 251.8 | G39: 240.6 | H39: 232.3
A40: D&A (PPE + Intangibles) | B40: £m | C40: 32.7 | D40: 33.2 | E40: 31.8 | F40: 30.5 | G40: 29.8 | H40: 30.4
A41: D of Right-of-Use Assets | B41: £m | C41: 0 | D41: 45.1 | E41: 45.7 | F41: 48.6 | G41: 49.3 | H41: 50.2
A42: Capital Expenditure (PPE) | B42: £m | C42: -12 | D42: -20.5 | E42: -15.1 | F42: -23.3 | G42: -21.4 | H42: -29.8
A43: Acquisition of Intangibles | B43: £m | C43: -13 | D43: -4.4 | E43: -0.6 | F43: -0.7 | G43: -0.4 | H43: -2.6
A44: Net Cash from Investing | B44: £m | C44: -19.6 | D44: -24.8 | E44: -15.6 | F44: -41.6 | G44: -20.7 | H44: -38.3
A45: Dividends Paid | B45: £m | C45: -54.6 | D45: -106 | E45: -24.3 | F45: -282.1 | G45: -163.3 | H45: -157.6
A46: RCF Drawdowns | B46: £m | C46: 25 | D46: 165 | E46: 0 | F46: 85 | G46: 139 | H46: 110
A47: RCF Repayments | B47: £m | C47: -120 | D47: -165 | E47: -45 | F47: -31 | G47: -116 | H47: -108
...

Sheet Chemring_Data
A1: CHEMRING GROUP PLC — SOURCE DATA
A2: Income Statement, Balance Sheet & Cash Flow | 2020–2025 | Values in £m except EPS (pence)
A3: Line Item | B3: Unit | C3: 2020 | D3: 2021 | E3: 2022 | F3: 2023 | G3: 2024 | H3: 2025
A4: INCOME STATEMENT
A5: Revenue | B5: £m | C5: 402.5 | D5: 393.3 | E5: 401 | F5: 472.6 | G5: 488.3 | H5: 497.5
A6: Operating Profit (Total) | B6: £m | C6: 46.3 | D6: 50.4 | E6: 49.4 | F6: 45.4 | G6: 56.6 | H6: 73.4
A7: Operating Profit (Underlying) | B7: £m | C7: 54.7 | D7: 57.5 | E7: 59.4 | F7: 69.2 | G7: - | H7: -
A8: Finance Expense | B8: £m | C8: -3 | D8: -1.6 | E8: -1.5 | F8: -1.3 | G8: -4.8 | H8: -5.7
A9: Profit Before Tax (Total) | B9: £m | C9: 43.3 | D9: 48.8 | E9: 47.9 | F9: 44.1 | G9: 51.8 | H9: 67.7
A10: Taxation | B10: £m | C10: -8.6 | D10: -7.3 | E10: -3.5 | F10: -6.4 | G10: -10.3 | H10: -14.4
A11: PAT – Continuing (Total) | B11: £m | C11: 34.7 | D11: 41.5 | E11: 44.4 | F11: 37.7 | G11: 41.5 | H11: 53.3
A12: Disc. Operations after Tax | B12: £m | C12: 0 | D12: 0 | E12: 3 | F12: -32.3 | G12: -2 | H12: -5.1
A13: Total Profit After Tax | B13: £m | C13: 34.7 | D13: 41.5 | E13: 47.4 | F13: 5.4 | G13: 39.5 | H13: 48.2
A14: EPS Basic – Continuing (p) | B14: p | C14: 12.3 | D14: 14.7 | E14: 15.8 | F14: 13.4 | G14: 15.2 | H14: 19.7
A15: EPS Diluted – Continuing (p) | B15: p | C15: 12 | D15: 14.4 | E15: 15.4 | F15: 13.1 | G15: 14.9 | H15: 19.3
A16: EPS Basic – Total (p) | B16: p | C16: 12.3 | D16: 14.7 | E16: 16.9 | F16: 1.9 | G16: 14.5 | H16: 17.8
A17: EPS Diluted – Total (p) | B17: p | C17: 12 | D17: 14.4 | E17: 16.4 | F17: 1.9 | G17: 14.1 | H17: 17.5
A19: BALANCE SHEET
A20: Goodwill | B20: £m | C20: 108.5 | D20: 108.7 | E20: 118.1 | F20: 100.5 | G20: 98.5 | H20: 99.6
A21: Development Costs | B21: £m | C21: 29.8 | D21: 30 | E21: 34.6 | F21: 17.6 | G21: 18.6 | H21: 20.2
A22: Other Intangibles | B22: £m | C22: 16.6 | D22: 14.1 | E22: 11.4 | F22: 9.6 | G22: 10 | H22: 43.7
A23: Property, Plant & Equipment | B23: £m | C23: 194 | D23: 198.7 | E23: 231.3 | F23: 242.2 | G23: 287.8 | H23: 354.7
A24: Deferred Tax Asset | B24: £m | C24: 15.7 | D24: 18.2 | E24: 32.3 | F24: 36.9 | G24: 7.3 | H24: 11.2
A25: Total Non-Current Assets | B25: £m | C25: 372.2 | D25: 383.4 | E25: 438.9 | F25: 412.7 | G25: 422.3 | H25: 531.3
A26: Inventories | B26: £m | C26: 91.3 | D26: 80.7 | E26: 99.6 | F26: 101.7 | G26: 127.1 | H26: 143.2
A27: Trade & Other Receivables | B27: £m | C27: 62.8 | D27: 60.6 | E27: 61.1 | F27: 74.8 | G27: 91 | H27: 110.5
A28: Cash & Equivalents | B28: £m | C28: 14.7 | D28: 5.8 | E28: 19.8 | F28: 6.4 | G28: 45 | H28: 65.3
A29: Total Current Assets | B29: £m | C29: 169.2 | D29: 148.1 | E29: 181.2 | F29: 183.7 | G29: 264 | H29: 321.5
A30: Total Assets | B30: £m | C30: 541.4 | D30: 531.5 | E30: 620.1 | F30: 596.4 | G30: 692.1 | H30: 863.1
A31: Borrowings – Current | B31: £m | C31: 0 | D31: -0.4 | E31: 0 | F31: 0 | G31: -43 | H31: -47.2
... A39: Share Capital + Premium | B39: £m | C39: 309.5 | D39: 309.9 | E39: 310.5 | F39: 311.5 | G39: 311.7 | H39: 311.9
A41: CASH FLOW STATEMENT
A42: Net Cash from Operations | B42: £m | C42: 75.9 | D42: 75.7 | E42: 80.5 | F42: 65.9 | G42: 81 | H42: 91.1
A43: Capex – PPE | B43: £m | C43: -35.6 | D43: -28 | E43: -31.5 | F43: -32.7 | G43: -63 | H43: -90.2
A44: Capex – Intangibles | B44: £m | C44: -5.2 | D44: -2.2 | E44: -3 | F44: -1.5 | G44: -4.8 | H44: -12.1
A45: Net Cash from Investing | B45: £m | C45: -25.4 | D45: -34.9 | E45: -30.5 | F45: -39.4 | G45: -47.6 | H45: -88.9
A46: Dividends Paid | B46: £m | C46: -10.4 | D46: -11.9 | E46: -14.4 | F46: -17.3 | G46: -19.6 | H46: -21.5
A47: Purchase of Own Shares | B47: £m | C47: -2.4 | D47: -7.1 | E47: -7 | F47: -14 | G47: -41 | H47: -6.6
A48: Drawdown of Borrowings | B48: £m | C48: 108 | D48: 29.2 | E48: 30 | F48: 60.1 | G48: 100 | H48: 145
A49: Repayments of Borrowings | B49: £m | C49: -123.1 | D49: -55.7 | E49: -41 | F49: -66.8 | G49: -70.1 | H49: -70
...

Sheet 1_FSA
A1: FINANCIAL STATEMENT ANALYSIS
A2: Trend analysis across all key P&L, Balance Sheet and Cash Flow metrics | Blue = hardcoded input | Black = Excel formula | Green = cross-sheet link
A3: Metric | B3: Formula Used | C3: FY2019 | D3: FY2020 | E3: FY2021 | F3: FY2022 | G3: FY2023 | H3: FY2024 | J3: FY2020 | K3: FY2021 | L3: FY2022 | M3: FY2023 | N3: FY2024 | O3: FY2025 | P3: Analyst Notes
B4: ← Formula is shown in this column for transparency | C4: DUNELM GROUP PLC | J4: CHEMRING GROUP PLC
A5: ▸ 1.1 REVENUE TREND
A6: Revenue (£m) | B6: =direct link to income statement revenue row | C6: =Dunelm_Data!C5 -> 1100.4 | D6: =Dunelm_Data!D5 -> 1057.9 | E6: =Dunelm_Data!E5 -> 1336.2 | F6: =Dunelm_Data!F5 -> 1581.4 | G6: =Dunelm_Data!G5 -> 1638.8 | H6: =Dunelm_Data!H5 -> 1706.5 | J6: =Chemring_Data!C5 -> 402.5 | K6: =Chemring_Data!D5 -> 393.3 | L6: =Chemring_Data!E5 -> 401 | M6: =Chemring_Data!F5 -> 472.6 | N6: =Chemring_Data!G5 -> 488.3 | O6: =Chemring_Data!H5 -> 497.5 | P6: Dunelm: Strong retail growth; Chemring: Gradual defence ramp
A7: Revenue YoY Growth (%) | B7: =(revenue_year_n - revenue_year_n-1) / revenue_year_n-1 | C7: n/a | D7: =(Dunelm_Data!D5-Dunelm_Data!C5)/Dunelm_Data!C5 -> -0.038622319 | E7: =(Dunelm_Data!E5-Dunelm_Data!D5)/Dunelm_Data!D5 -> 0.26306834 | F7: =(Dunelm_Data!F5-Dunelm_Data!E5)/Dunelm_Data!E5 -> 0.18350546 | G7: =(Dunelm_Data!G5-Dunelm_Data!F5)/Dunelm_Data!F5 -> 0.036296952 | H7: =(Dunelm_Data!H5-Dunelm_Data!G5)/Dunelm_Data!G5 -> 0.041310715 | J7: n/a | K7: =(Chemring_Data!D5-Chemring_Data!C5)/Chemring_Data!C5 -> -0.022857143 | L7: =(Chemring_Data!E5-Chemring_Data!D5)/Chemring_Data!D5 -> 0.01957793 | M7: =(Chemring_Data!F5-Chemring_Data!E5)/Chemring_Data!E5 -> 0.17855362 | N7: =(Chemring_Data!G5-Chemring_Data!F5)/Chemring_Data!F5 -> 0.033220482 | O7: =(Chemring_Data!H5-Chemring_Data!G5)/Chemring_Data!G5 -> 0.018840877 | P7: Dunelm dip FY20 (COVID); surge FY21-22; Chemring steady
A8: Revenue CAGR to Date (%) | B8: =(revenue_year_n / revenue_base_year)^(1/n) - 1 | C8: base | D8: =(Dunelm_Data!D5/Dunelm_Data!C5)^(1/1)-1 -> -0.038622319 | E8: =(Dunelm_Data!E5/Dunelm_Data!C5)^(1/2)-1 -> 0.10194633 | F8: =(Dunelm_Data!F5/Dunelm_Data!C5)^(1/3)-1 -> 0.12848827 | G8: =(Dunelm_Data!G5/Dunelm_Data!C5)^(1/4)-1 -> 0.1046987 | H8: =(Dunelm_Data!H5/Dunelm_Data!C5)^(1/5)-1 -> 0.091719687 | J8: base | K8: =(Chemring_Data!D5/Chemring_Data!C5)^(1/1)-1 -> -0.022857143 | L8: =(Chemring_Data!E5/Chemring_Data!C5)^(1/2)-1 -> -0.0018650933 | M8: =(Chemring_Data!F5/Chemring_Data!C5)^(1/3)-1 -> 0.054976075 | N8: =(Chemring_Data!G5/Chemring_Data!C5)^(1/4)-1 -> 0.049494604 | O8: =(Chemring_Data!H5/Chemring_Data!C5)^(1/5)-1 -> 0.04329095 | P8: Dunelm CAGR ~9.2% (2019-2024); Chemring ~4.3% (2020-2025)
A10: ▸ 1.2 GROSS PROFIT TREND
A11: Gross Profit / EBIT (£m) | B11: Dunelm: ='Dunelm_Data'!Revenue row - CoS row | Chemring: Operating Profit (no COGS split reported) | C11: =Dunelm_Data!C7 -> 545.6 | D11: =Dunelm_Data!D7 -> 532.4 | E11: =Dunelm_Data!E7 -> 688.9 | F11: =Dunelm_Data!F7 -> 809.4 | G11: =Dunelm_Data!G7 -> 820.9 | H11: =Dunelm_Data!H7 -> 883.3 | J11: =Chemring_Data!C6 -> 46.3 | K11: =Chemring_Data!D6 -> 50.4 | L11: =Chemring_Data!E6 -> 49.4 | M11: =Chemring_Data!F6 -> 45.4 | N11: =Chemring_Data!G6 -> 56.6 | O11: =Chemring_Data!H6 -> 73.4 | P11: Chemring gross profit not separately disclosed; EBIT used
A12: YoY Growth (%) | B12: =(gp_n - gp_n-1) / |gp_n-1| | C12: n/a | D12: =(Dunelm_Data!D7-Dunelm_Data!C7)/Dunelm_Data!C7 -> -0.024193548 | E12: =(Dunelm_Data!E7-Dunelm_Data!D7)/Dunelm_Data!D7 -> 0.29395192 | F12: =(Dunelm_Data!F7-Dunelm_Data!E7)/Dunelm_Data!E7 -> 0.17491653 | G12: =(Dunelm_Data!G7-Dunelm_Data!F7)/Dunelm_Data!F7 -> 0.014208055 | H12: =(Dunelm_Data!H7-Dunelm_Data!G7)/Dunelm_Data!G7 -> 0.076014131 | J12: n/a | K12: =(Chemring_Data!D6-Chemring_Data!C6)/Chemring_Data!C6 -> 0.088552916 | L12: =(Chemring_Data!E6-Chemring_Data!D6)/Chemring_Data!D6 -> -0.01984127 | M12: =(Chemring_Data!F6-Chemring_Data!E6)/Chemring_Data!E6 -> -0.08097166 | N12: =(Chemring_Data!G6-Chemring_Data!F6)/Chemring_Data!F6 -> 0.24669604 | O12: =(Chemring_Data!H6-Chemring_Data!G6)/Chemring_Data!G6 -> 0.29681979 | P12: Dunelm GP grew 62% over 5yr; Chemring EBIT +58%
A14: ▸ 1.3 OPERATING PROFIT TREND
A15: Operating Profit / EBIT (£m) | B15: =revenue - cost of sales - operating costs [pulled from is rows] | C15: =Dunelm_Data!C9 -> 126.9 | D15: =Dunelm_Data!D9 -> 116 | E15: =Dunelm_Data!E9 -> 166.4 | F15: =Dunelm_Data!F9 -> 217.7 | G15: =Dunelm_Data!G9 -> 198.8 | H15: =Dunelm_Data!H9 -> 213.3 | J15: =Chemring_Data!C6 -> 46.3 | K15: =Chemring_Data!D6 -> 50.4 | L15: =Chemring_Data!E6 -> 49.4 | M15: =Chemring_Data!F6 -> 45.4 | N15: =Chemring_Data!G6 -> 56.6 | O15: =Chemring_Data!H6 -> 73.4 | P15: Dunelm £213m (FY24); Chemring £73m (FY25)
A16: EBIT YoY Growth (%) | B16: =(ebit_n - ebit_n-1) / ebit_n-1 | C16: n/a | D16: =(Dunelm_Data!D9-Dunelm_Data!C9)/Dunelm_Data!C9 -> -0.085894405 | E16: =(Dunelm_Data!E9-Dunelm_Data!D9)/Dunelm_Data!D9 -> 0.43448276 | F16: =(Dunelm_Data!F9-Dunelm_Data!E9)/Dunelm_Data!E9 -> 0.30829327 | G16: =(Dunelm_Data!G9-Dunelm_Data!F9)/Dunelm_Data!F9 -> -0.08681672 | H16: =(Dunelm_Data!H9-Dunelm_Data!G9)/Dunelm_Data!G9 -> 0.072937626 | J16: n/a | K16: =(Chemring_Data!D6-Chemring_Data!C6)/Chemring_Data!C6 -> 0.088552916 | L16: =(Chemring_Data!E6-Chemring_Data!D6)/Chemring_Data!D6 -> -0.01984127 | M16: =(Chemring_Data!F6-Chemring_Data!E6)/Chemring_Data!E6 -> -0.08097166 | N16: =(Chemring_Data!G6-Chemring_Data!F6)/Chemring_Data!F6 -> 0.24669604 | O16: =(Chemring_Data!H6-Chemring_Data!G6)/Chemring_Data!G6 -> 0.29681979 | P16: Dunelm EBIT volatile; Chemring FY25 breakout +29.7%
A18: ▸ 1.4 PROFIT AFTER TAX TREND
A19: Profit After Tax (£m) | B19: =profit before tax + taxation [linked from is] | C19: =Dunelm_Data!C14 -> 101.3 | D19: =Dunelm_Data!D14 -> 87.7 | E19: =Dunelm_Data!E14 -> 128.9 | F19: =Dunelm_Data!F14 -> 171.2 | G19: =Dunelm_Data!G14 -> 151.9 | H19: =Dunelm_Data!H14 -> 151.2 | J19: =Chemring_Data!C13 -> 34.7 | K19: =Chemring_Data!D13 -> 41.5 | L19: =Chemring_Data!E13 -> 47.4 | M19: =Chemring_Data!F13 -> 5.4 | N19: =Chemring_Data!G13 -> 39.5 | O19: =Chemring_Data!H13 -> 48.2 | P19: Chemring FY23 PAT distorted by disc. ops loss of £32.3m
A20: PAT YoY Growth (%) | B20: =(pat_n - pat_n-1) / ABS(pat_n-1) | C20: n/a | D20: =(Dunelm_Data!D14-Dunelm_Data!C14)/Dunelm_Data!C14 -> -0.13425469 | E20: =(Dunelm_Data!E14-Dunelm_Data!D14)/Dunelm_Data!D14 -> 0.46978335 | F20: =(Dunelm_Data!F14-Dunelm_Data!E14)/Dunelm_Data!E14 -> 0.32816137 | G20: =(Dunelm_Data!G14-Dunelm_Data!F14)/Dunelm_Data!F14 -> -0.11273364 | H20: =(Dunelm_Data!H14-Dunelm_Data!G14)/Dunelm_Data!G14 -> -0.0046082949 | J20: n/a | K20: =(Chemring_Data!D13-Chemring_Data!C13)/Chemring_Data!C13 -> 0.19596542 | L20: =(Chemring_Data!E13-Chemring_Data!D13)/Chemring_Data!D13 -> 0.14216867 | M20: =(Chemring_Data!F13-Chemring_Data!E13)/Chemring_Data!E13 -> -0.88607595 | N20: =(Chemring_Data!G13-Chemring_Data!F13)/Chemring_Data!F13 -> 6.3148148 | O20: =(Chemring_Data!H13-Chemring_Data!G13)/Chemring_Data!G13 -> 0.22025316 | P20: Chemring FY23 misleadingly negative; use continuing ops
A22: ▸ 1.5 EARNINGS PER SHARE TREND
A23: EPS Basic – Continuing (p) | B23: =profit after tax / weighted average shares [from is per-share data] | C23: =Dunelm_Data!C15 -> 50.2 | D23: =Dunelm_Data!D15 -> 43.4 | E23: =Dunelm_Data!E15 -> 63.7 | F23: =Dunelm_Data!F15 -> 84.5 | G23: =Dunelm_Data!G15 -> 75.2 | H23: =Dunelm_Data!H15 -> 74.7 | J23: =Chemring_Data!C14 -> 12.3 | K23: =Chemring_Data!D14 -> 14.7 | L23: =Chemring_Data!E14 -> 15.8 | M23: =Chemring_Data!F14 -> 13.4 | N23: =Chemring_Data!G14 -> 15.2 | O23: =Chemring_Data!H14 -> 19.7 | P23: Dunelm EPS peaked FY22 84.5p; Chemring FY25 19.7p record
A24: EPS Diluted – Continuing (p) | B24: =diluted pat / diluted weighted avg shares | C24: =Dunelm_Data!C16 -> 49.9 | D24: =Dunelm_Data!D16 -> 42.9 | E24: =Dunelm_Data!E16 -> 62.9 | F24: =Dunelm_Data!F16 -> 83.6 | G24: =Dunelm_Data!G16 -> 75 | H24: =Dunelm_Data!H16 -> 74.4 | J24: =Chemring_Data!C15 -> 12 | K24: =Chemring_Data!D15 -> 14.4 | L24: =Chemring_Data!E15 -> 15.4 | M24: =Chemring_Data!F15 -> 13.1 | N24: =Chemring_Data!G15 -> 14.9 | O24: =Chemring_Data!H15 -> 19.3 | P24: Dilution effect minimal for both companies
A25: EPS Growth YoY (%) | B25: =(eps_n - eps_n-1) / eps_n-1 | C25: n/a | D25: =(Dunelm_Data!D15-Dunelm_Data!C15)/Dunelm_Data!C15 -> -0.13545817 | E25: =(Dunelm_Data!E15-Dunelm_Data!D15)/Dunelm_Data!D15 -> 0.46774194 | F25: =(Dunelm_Data!F15-Dunelm_Data!E15)/Dunelm_Data!E15 -> 0.32653061 | G25: =(Dunelm_Data!G15-Dunelm_Data!F15)/Dunelm_Data!F15 -> -0.11005917 | H25: =(Dunelm_Data!H15-Dunelm_Data!G15)/Dunelm_Data!G15 -> -0.0066489362 | J25: n/a | K25: =(Chemring_Data!D14-Chemring_Data!C14)/Chemring_Data!C14 -> 0.19512195 | L25: =(Chemring_Data!E14-Chemring_Data!D14)/Chemring_Data!D14 -> 0.074829932 | M25: =(Chemring_Data!F14-Chemring_Data!E14)/Chemring_Data!E14 -> -0.15189873 | N25: =(Chemring_Data!G14-Chemring_Data!F14)/Chemring_Data!F14 -> 0.13432836 | O25: =(Chemring_Data!H14-Chemring_Data!G14)/Chemring_Data!G14 -> 0.29605263 | P25: Both companies show positive CAGR despite single-year dips
A27: ▸ 1.6 DIVIDEND PER SHARE TREND
A28: Dividend Per Share (p) | B28: =total dividends paid / shares outstanding [from supplementary data] | C28: =Dunelm_Data!C55 -> 27.1 | D28: =Dunelm_Data!D55 -> 52.5 | E28: =Dunelm_Data!E55 -> 12 | F28: =Dunelm_Data!F55 -> 139.2 | G28: =Dunelm_Data!G55 -> 80.8 | H28: =Dunelm_Data!H55 -> 77.8 | J28: =Chemring_Data!C55 -> 3.7 | K28: =Chemring_Data!D55 -> 4.2 | L28: =Chemring_Data!E55 -> 5.1 | M28: =Chemring_Data!F55 -> 6.3 | N28: =Chemring_Data!G55 -> 7.2 | O28: =Chemring_Data!H55 -> 7.9 | P28: Dunelm paid very large special divs FY20, FY22; Chemring progressive
A29: DPS YoY Growth (%) | B29: =(dps_n - dps_n-1) / dps_n-1 | C29: n/a | D29: =(Dunelm_Data!D55-Dunelm_Data!C55)/Dunelm_Data!C55 -> 0.93726937 | E29: =(Dunelm_Data!E55-Dunelm_Data!D55)/Dunelm_Data!D55 -> -0.77142857 | F29: =(Dunelm_Data!F55-Dunelm_Data!E55)/Dunelm_Data!E55 -> 10.6 | G29: =(Dunelm_Data!G55-Dunelm_Data!F55)/Dunelm_Data!F55 -> -0.41954023 | H29: =(Dunelm_Data!H55-Dunelm_Data!G55)/Dunelm_Data!G55 -> -0.037128713 | J29: n/a | K29: =(Chemring_Data!D55-Chemring_Data!C55)/Chemring_Data!C55 -> 0.13513514 | L29: =(Chemring_Data!E55-Chemring_Data!D55)/Chemring_Data!D55 -> 0.21428571 | M29: =(Chemring_Data!F55-Chemring_Data!E55)/Chemring_Data!E55 -> 0.23529412 | N29: =(Chemring_Data!G55-Chemring_Data!F55)/Chemring_Data!F55 -> 0.14285714 | O29: =(Chemring_Data!H55-Chemring_Data!G55)/Chemring_Data!G55 -> 0.097222222 | P29: Dunelm DPS erratic (special dividends); Chemring steady growth
A31: ▸ 1.7 ASSET GROWTH TREND
A32: Total Assets (£m) | B32: =total non-current assets + total current assets [balance sheet link] | C32: =Dunelm_Data!C27 -> 417.1 | D32: =Dunelm_Data!D27 -> 716 | E32: =Dunelm_Data!E27 -> 766.7 | F32: =Dunelm_Data!F27 -> 737.9 | G32: =Dunelm_Data!G27 -> 696.8 | H32: =Dunelm_Data!H27 -> 682 | J32: =Chemring_Data!C30 -> 541.4 | K32: =Chemring_Data!D30 -> 531.5 | L32: =Chemring_Data!E30 -> 620.1 | M32: =Chemring_Data!F30 -> 596.4 | N32: =Chemring_Data!G30 -> 692.1 | O32: =Chemring_Data!H30 -> 863.1 | P32: Dunelm assets declined post-IFRS16 peak; Chemring +59% from M&A/capex
A33: Asset YoY Growth (%) | B33: =(total assets_n - total assets_n-1) / total assets_n-1 | C33: n/a | D33: =(Dunelm_Data!D27-Dunelm_Data!C27)/Dunelm_Data!C27 -> 0.71661472 | E33: =(Dunelm_Data!E27-Dunelm_Data!D27)/Dunelm_Data!D27 -> 0.070810056 | F33: =(Dunelm_Data!F27-Dunelm_Data!E27)/Dunelm_Data!E27 -> -0.037563584 | G33: =(Dunelm_Data!G27-Dunelm_Data!F27)/Dunelm_Data!F27 -> -0.055698604 | H33: =(Dunelm_Data!H27-Dunelm_Data!G27)/Dunelm_Data!G27 -> -0.021239954 | J33: n/a | K33: =(Chemring_Data!D30-Chemring_Data!C30)/Chemring_Data!C30 -> -0.018285925 | L33: =(Chemring_Data!E30-Chemring_Data!D30)/Chemring_Data!D30 -> 0.16669802 | M33: =(Chemring_Data!F30-Chemring_Data!E30)/Chemring_Data!E30 -> -0.038219642 | N33: =(Chemring_Data!G30-Chemring_Data!F30)/Chemring_Data!F30 -> 0.16046278 | O33: =(Chemring_Data!H30-Chemring_Data!G30)/Chemring_Data!G30 -> 0.24707412 | P33: Chemring FY25 asset base accelerates with defence contracts
A35: ▸ 1.8 EQUITY TREND
A36: Total Equity (£m) | B36: =total assets - total liabilities [balance sheet net assets] | C36: =Dunelm_Data!C35 -> 185.8 | D36: =Dunelm_Data!D35 -> 173.4 | E36: =Dunelm_Data!E35 -> 281.2 | F36: =Dunelm_Data!F35 -> 178.3 | G36: =Dunelm_Data!G35 -> 137.5 | H36: =Dunelm_Data!H35 -> 137.9 | J36: =Chemring_Data!C37 -> 329.6 | K36: =Chemring_Data!D37 -> 352.8 | L36: =Chemring_Data!E37 -> 418.1 | M36: =Chemring_Data!F37 -> 378.5 | N36: =Chemring_Data!G37 -> 356.3 | O36: =Chemring_Data!H37 -> 382 | P36: Dunelm equity eroded by large special dividends; Chemring stable
A37: Equity YoY Change (%) | B37: =(equity_n - equity_n-1) / |equity_n-1| | C37: n/a | D37: =(Dunelm_Data!D35-Dunelm_Data!C35)/Dunelm_Data!C35 -> -0.066738428 | E37: =(Dunelm_Data!E35-Dunelm_Data!D35)/Dunelm_Data!D35 -> 0.62168397 | F37: =(Dunelm_Data!F35-Dunelm_Data!E35)/Dunelm_Data!E35 -> -0.36593172 | G37: =(Dunelm_Data!G35-Dunelm_Data!F35)/Dunelm_Data!F35 -> -0.22882782 | H37: =(Dunelm_Data!H35-Dunelm_Data!G35)/Dunelm_Data!G35 -> 0.0029090909 | J37: n/a | K37: =(Chemring_Data!D37-Chemring_Data!C37)/Chemring_Data!C37 -> 0.07038835 | L37: =(Chemring_Data!E37-Chemring_Data!D37)/Chemring_Data!D37 -> 0.1850907 | M37: =(Chemring_Data!F37-Chemring_Data!E37)/Chemring_Data!E37 -> -0.094714183 | N37: =(Chemring_Data!G37-Chemring_Data!F37)/Chemring_Data!F37 -> -0.058652576 | O37: =(Chemring_Data!H37-Chemring_Data!G37)/Chemring_Data!G37 -> 0.072130227 | P37: Dunelm equity thin; shareholders rewarded via cash distributions
A39: ▸ 1.9 DEBT TREND
A40: Financial Debt – excl. leases (£m) | B40: Dunelm: =ABS(Bank Loans) | Chemring: =ABS(Borrowings_Current) + ABS(Borrowings_NonCurrent) | C40: =ABS(Dunelm_Data!C32) -> 44.3 | D40: =ABS(Dunelm_Data!D32) -> 44.6 | E40: =ABS(Dunelm_Data!E32) -> 0 | F40: =ABS(Dunelm_Data!F32) -> 52.8 | G40: =ABS(Dunelm_Data!G32) -> 75.9 | H40: =ABS(Dunelm_Data!H32) -> 77 | J40: =ABS(Chemring_Data!C31)+ABS(Chemring_Data!C34) -> 57.5 | K40: =ABS(Chemring_Data!D31)+ABS(Chemring_Data!D34) -> 28.5 | L40: =ABS(Chemring_Data!E31)+ABS(Chemring_Data!E34) -> 20.9 | M40: =ABS(Chemring_Data!F31)+ABS(Chemring_Data!F34) -> 14.1 | N40: =ABS(Chemring_Data!G31)+ABS(Chemring_Data!G34) -> 86.7 | O40: =ABS(Chemring_Data!H31)+ABS(Chemring_Data!H34) -> 138.8 | P40: Chemring debt surged FY24-25 to fund investment; Dunelm RCF modest
A41: Total Liabilities (£m) | B41: =ABS(total liabilities row from balance sheet) | C41: =ABS(Dunelm_Data!C34) -> 231.3 | D41: =ABS(Dunelm_Data!D34) -> 542.6 | E41: =ABS(Dunelm_Data!E34) -> 485.5 | F41: =ABS(Dunelm_Data!F34) -> 559.6 | G41: =ABS(Dunelm_Data!G34) -> 559.3 | H41: =ABS(Dunelm_Data!H34) -> 544.1 | J41: =ABS(Chemring_Data!C36) -> 211.8 | K41: =ABS(Chemring_Data!D36) -> 178.7 | L41: =ABS(Chemring_Data!E36) -> 202 | M41: =ABS(Chemring_Data!F36) -> 217.9 | N41: =ABS(Chemring_Data!G36) -> 335.8 | O41: =ABS(Chemring_Data!H36) -> 481.1 | P41: Includes lease liabilities; Dunelm lease-heavy due to store estate
A43: Note: Blue cells = hardcoded source inputs in Data sheets. Black cells = Excel formulas computed from source data. Formula column shows the calculation logic.

Sheet 2_Profitability
A1: PROFITABILITY ANALYSIS
A2: Margin movement, cost efficiency, return to shareholders, profit quality & sustainability
A3: Metric | B3: Formula Used | C3: FY2019 | D3: FY2020 | E3: FY2021 | F3: FY2022 | G3: FY2023 | H3: FY2024 | J3: FY2020 | K3: FY2021 | L3: FY2022 | M3: FY2023 | N3: FY2024 | O3: FY2025 | P3: Analyst Notes
B4: ← Formula logic shown here | C4: DUNELM GROUP PLC | J4: CHEMRING GROUP PLC
A5: ▸ 2.1 MARGIN MOVEMENT
A6: Gross Margin (%) – Dunelm / EBIT Margin – Chemring | B6: Dunelm: = Gross Profit / Revenue | Chemring: = Operating Profit / Revenue | C6: =Dunelm_Data!C7/Dunelm_Data!C5 -> 0.4958197 | D6: =Dunelm_Data!D7/Dunelm_Data!D5 -> 0.50326118 | E6: =Dunelm_Data!E7/Dunelm_Data!E5 -> 0.51556653 | F6: =Dunelm_Data!F7/Dunelm_Data!F5 -> 0.51182497 | G6: =Dunelm_Data!G7/Dunelm_Data!G5 -> 0.5009153 | H6: =Dunelm_Data!H7/Dunelm_Data!H5 -> 0.51760914 | J6: =Chemring_Data!C6/Chemring_Data!C5 -> 0.11503106 | K6: =Chemring_Data!D6/Chemring_Data!D5 -> 0.12814645 | L6: =Chemring_Data!E6/Chemring_Data!E5 -> 0.12319202 | M6: =Chemring_Data!F6/Chemring_Data!F5 -> 0.096064325 | N6: =Chemring_Data!G6/Chemring_Data!G5 -> 0.11591235 | O6: =Chemring_Data!H6/Chemring_Data!H5 -> 0.14753769 | P6: Dunelm GM ~50%; Chemring EBIT margin expanding to 14.8% in FY25
A7: Operating (EBIT) Margin (%) | B7: =operating profit / revenue | C7: =Dunelm_Data!C9/Dunelm_Data!C5 -> 0.1153217 | D7: =Dunelm_Data!D9/Dunelm_Data!D5 -> 0.1096512 | E7: =Dunelm_Data!E9/Dunelm_Data!E5 -> 0.12453226 | F7: =Dunelm_Data!F9/Dunelm_Data!F5 -> 0.13766283 | G7: =Dunelm_Data!G9/Dunelm_Data!G5 -> 0.12130827 | H7: =Dunelm_Data!H9/Dunelm_Data!H5 -> 0.12499268 | J7: =Chemring_Data!C6/Chemring_Data!C5 -> 0.11503106 | K7: =Chemring_Data!D6/Chemring_Data!D5 -> 0.12814645 | L7: =Chemring_Data!E6/Chemring_Data!E5 -> 0.12319202 | M7: =Chemring_Data!F6/Chemring_Data!F5 -> 0.096064325 | N7: =Chemring_Data!G6/Chemring_Data!G5 -> 0.11591235 | O7: =Chemring_Data!H6/Chemring_Data!H5 -> 0.14753769 | P7: Dunelm peaked FY22 13.8%; Chemring FY25 highest at 14.8%
A8: Net Profit Margin (%) | B8: =profit after tax / revenue | C8: =Dunelm_Data!C14/Dunelm_Data!C5 -> 0.092057434 | D8: =Dunelm_Data!D14/Dunelm_Data!D5 -> 0.082900085 | E8: =Dunelm_Data!E14/Dunelm_Data!E5 -> 0.096467595 | F8: =Dunelm_Data!F14/Dunelm_Data!F5 -> 0.10825851 | G8: =Dunelm_Data!G14/Dunelm_Data!G5 -> 0.092689773 | H8: =Dunelm_Data!H14/Dunelm_Data!H5 -> 0.088602403 | J8: =Chemring_Data!C13/Chemring_Data!C5 -> 0.08621118 | K8: =Chemring_Data!D13/Chemring_Data!D5 -> 0.10551742 | L8: =Chemring_Data!E13/Chemring_Data!E5 -> 0.11820449 | M8: =Chemring_Data!F13/Chemring_Data!F5 -> 0.011426153 | N8: =Chemring_Data!G13/Chemring_Data!G5 -> 0.080892894 | O8: =Chemring_Data!H13/Chemring_Data!H5 -> 0.096884422 | P8: Chemring FY23 net margin distorted; use continuing ops basis
A9: PBT Margin (%) | B9: =profit before tax / revenue | C9: =Dunelm_Data!C12/Dunelm_Data!C5 -> 0.11441294 | D9: =Dunelm_Data!D12/Dunelm_Data!D5 -> 0.10312884 | E9: =Dunelm_Data!E12/Dunelm_Data!E5 -> 0.11809609 | F9: =Dunelm_Data!F12/Dunelm_Data!F5 -> 0.13456431 | G9: =Dunelm_Data!G12/Dunelm_Data!G5 -> 0.11758604 | H9: =Dunelm_Data!H12/Dunelm_Data!H5 -> 0.12036332 | J9: =Chemring_Data!C9/Chemring_Data!C5 -> 0.10757764 | K9: =Chemring_Data!D9/Chemring_Data!D5 -> 0.12407831 | L9: =Chemring_Data!E9/Chemring_Data!E5 -> 0.11945137 | M9: =Chemring_Data!F9/Chemring_Data!F5 -> 0.093313584 | N9: =Chemring_Data!G9/Chemring_Data!G5 -> 0.10608233 | O9: =Chemring_Data!H9/Chemring_Data!H5 -> 0.1360804 | P9: More representative; excludes tax distortions
A11: ▸ 2.2 COST EFFICIENCY
A12: Cost of Sales as % Revenue | B12: Dunelm: = ABS(Cost of Sales) / Revenue | Chemring: not separately disclosed | C12: =ABS(Dunelm_Data!C6)/Dunelm_Data!C5 -> 0.5041803 | D12: =ABS(Dunelm_Data!D6)/Dunelm_Data!D5 -> 0.49673882 | E12: =ABS(Dunelm_Data!E6)/Dunelm_Data!E5 -> 0.48443347 | F12: =ABS(Dunelm_Data!F6)/Dunelm_Data!F5 -> 0.48817503 | G12: =ABS(Dunelm_Data!G6)/Dunelm_Data!G5 -> 0.4990847 | H12: =ABS(Dunelm_Data!H6)/Dunelm_Data!H5 -> 0.48239086 | J12: N/A (not disclosed) | K12: N/A (not disclosed) | L12: N/A (not disclosed) | M12: N/A (not disclosed) | N12: N/A (not disclosed) | O12: N/A (not disclosed) | P12: Dunelm CoS ratio improving slightly – supply chain efficiency gains
A13: Operating Costs as % Revenue | B13: Dunelm: = ABS(Operating Costs) / Revenue | C13: =ABS(Dunelm_Data!C8)/Dunelm_Data!C5 -> 0.380498 | D13: =ABS(Dunelm_Data!D8)/Dunelm_Data!D5 -> 0.39360998 | E13: =ABS(Dunelm_Data!E8)/Dunelm_Data!E5 -> 0.39103428 | F13: =ABS(Dunelm_Data!F8)/Dunelm_Data!F5 -> 0.37416213 | G13: =ABS(Dunelm_Data!G8)/Dunelm_Data!G5 -> 0.37960703 | H13: =ABS(Dunelm_Data!H8)/Dunelm_Data!H5 -> 0.39261647 | J13: N/A | K13: N/A | L13: N/A | M13: N/A | N13: N/A | O13: N/A | P13: Dunelm OpEx ratio broadly flat ~39%; good cost control vs revenue growth
A14: EBITDA (£m) | B14: =ebit + d&a (ppe+intangibles) + depreciation of right-of-use assets | C14: =Dunelm_Data!C9+Dunelm_Data!C40+Dunelm_Data!C41 -> 159.6 | D14: =Dunelm_Data!D9+Dunelm_Data!D40+Dunelm_Data!D41 -> 194.3 | E14: =Dunelm_Data!E9+Dunelm_Data!E40+Dunelm_Data!E41 -> 243.9 | F14: =Dunelm_Data!F9+Dunelm_Data!F40+Dunelm_Data!F41 -> 296.8 | G14: =Dunelm_Data!G9+Dunelm_Data!G40+Dunelm_Data!G41 -> 277.9 | H14: =Dunelm_Data!H9+Dunelm_Data!H40+Dunelm_Data!H41 -> 293.9 | J14: =Chemring_Data!C6+Chemring_Data!C56 -> 64.3 | K14: =Chemring_Data!D6+Chemring_Data!D56 -> 68.9 | L14: =Chemring_Data!E6+Chemring_Data!E56 -> 68.4 | M14: =Chemring_Data!F6+Chemring_Data!F56 -> 65.4 | N14: =Chemring_Data!G6+Chemring_Data!G56 -> 78.6 | O14: =Chemring_Data!H6+Chemring_Data!H56 -> 98.4 | P14: EBITDA better reflects cash generation capacity before lease costs
A15: EBITDA Margin (%) | B15: =ebitda / revenue | C15: =(Dunelm_Data!C9+Dunelm_Data!C40+Dunelm_Data!C41)/Dunelm_Data!C5 -> 0.14503817 | D15: =(Dunelm_Data!D9+Dunelm_Data!D40+Dunelm_Data!D41)/Dunelm_Data!D5 -> 0.18366575 | E15: =(Dunelm_Data!E9+Dunelm_Data!E40+Dunelm_Data!E41)/Dunelm_Data!E5 -> 0.18253256 | F15: =(Dunelm_Data!F9+Dunelm_Data!F40+Dunelm_Data!F41)/Dunelm_Data!F5 -> 0.1876818 | G15: =(Dunelm_Data!G9+Dunelm_Data!G40+Dunelm_Data!G41)/Dunelm_Data!G5 -> 0.1695753 | H15: =(Dunelm_Data!H9+Dunelm_Data!H40+Dunelm_Data!H41)/Dunelm_Data!H5 -> 0.17222385 | J15: =(Chemring_Data!C6+Chemring_Data!C56)/Chemring_Data!C5 -> 0.15975155 | K15: =(Chemring_Data!D6+Chemring_Data!D56)/Chemring_Data!D5 -> 0.17518434 | L15: =(Chemring_Data!E6+Chemring_Data!E56)/Chemring_Data!E5 -> 0.17057357 | M15: =(Chemring_Data!F6+Chemring_Data!F56)/Chemring_Data!F5 -> 0.13838341 | N15: =(Chemring_Data!G6+Chemring_Data!G56)/Chemring_Data!G5 -> 0.16096662 | O15: =(Chemring_Data!H6+Chemring_Data!H56)/Chemring_Data!H5 -> 0.19778894 | P15: Dunelm EBITDA margin ~25-27%; includes significant IFRS16 ROU D&A
A17: ▸ 2.3 RETURN TO SHAREHOLDERS
A18: Return on Equity – ROE (%) | B18: =pat / ((opening equity + closing equity) / 2) — 2-point average | C18: n/a | D18: =Dunelm_Data!D14/((Dunelm_Data!D35+Dunelm_Data!C35)/2) -> 0.48830735 | E18: =Dunelm_Data!E14/((Dunelm_Data!E35+Dunelm_Data!D35)/2) -> 0.56709195 | F18: =Dunelm_Data!F14/((Dunelm_Data!F35+Dunelm_Data!E35)/2) -> 0.74515778 | G18: =Dunelm_Data!G14/((Dunelm_Data!G35+Dunelm_Data!F35)/2) -> 0.96200127 | H18: =Dunelm_Data!H14/((Dunelm_Data!H35+Dunelm_Data!G35)/2) -> 1.0980392 | J18: n/a | K18: =Chemring_Data!D13/((Chemring_Data!D37+Chemring_Data!C37)/2) -> 0.12162954 | L18: =Chemring_Data!E13/((Chemring_Data!E37+Chemring_Data!D37)/2) -> 0.12297315 | M18: =Chemring_Data!F13/((Chemring_Data!F37+Chemring_Data!E37)/2) -> 0.01355762 | N18: =Chemring_Data!G13/((Chemring_Data!G37+Chemring_Data!F37)/2) -> 0.10751225 | O18: =Chemring_Data!H13/((Chemring_Data!H37+Chemring_Data!G37)/2) -> 0.13057023 | P18: Dunelm ROE very high (thin equity base); Chemring ~12% sustainable
A19: Return on Capital Employed – ROCE (%) | B19: =ebit / ((capital employed_n + capital employed_n-1) / 2) ce = total assets - current liabilities | C19: n/a | D19: =Dunelm_Data!D9/((Dunelm_Data!C27-ABS(Dunelm_Data!C28)+Dunelm_Data!D27-ABS(Dunelm_Data!D28))/2) -> 0.3070814 | E19: =Dunelm_Data!E9/((Dunelm_Data!D27-ABS(Dunelm_Data!D28)+Dunelm_Data!E27-ABS(Dunelm_Data!E28))/2) -> 0.3265947 | F19: =Dunelm_Data!F9/((Dunelm_Data!E27-ABS(Dunelm_Data!E28)+Dunelm_Data!F27-ABS(Dunelm_Data!F28))/2) -> 0.43860179 | G19: =Dunelm_Data!G9/((Dunelm_Data!F27-ABS(Dunelm_Data!F28)+Dunelm_Data!G27-ABS(Dunelm_Data!G28))/2) -> 0.44719379 | H19: =Dunelm_Data!H9/((Dunelm_Data!G27-ABS(Dunelm_Data!G28)+Dunelm_Data!H27-ABS(Dunelm_Data!H28))/2) -> 0.5044342 | J19: n/a | K19: =Chemring_Data!D6/((Chemring_Data!C30-ABS(Chemring_Data!C33)+Chemring_Data!D30-ABS(Chemring_Data!D33))/2) -> 0.11740042 | L19: =Chemring_Data!E6/((Chemring_Data!D30-ABS(Chemring_Data!D33)+Chemring_Data!E30-ABS(Chemring_Data!E33))/2) -> 0.10562326 | M19: =Chemring_Data!F6/((Chemring_Data!E30-ABS(Chemring_Data!E33)+Chemring_Data!F30-ABS(Chemring_Data!F33))/2) -> 0.094514417 | N19: =Chemring_Data!G6/((Chemring_Data!F30-ABS(Chemring_Data!F33)+Chemring_Data!G30-ABS(Chemring_Data!G33))/2) -> 0.11597172 | O19: =Chemring_Data!H6/((Chemring_Data!G30-ABS(Chemring_Data!G33)+Chemring_Data!H30-ABS(Chemring_Data!H33))/2) -> 0.12403887 | P19: Dunelm ROCE strong ~35-50%; Chemring lower ~10-15% but improving
A20: Return on Assets – ROA (%) | B20: =pat / total assets | C20: =Dunelm_Data!C14/Dunelm_Data!C27 -> 0.24286742 | D20: =Dunelm_Data!D14/Dunelm_Data!D27 -> 0.12248603 | E20: =Dunelm_Data!E14/Dunelm_Data!E27 -> 0.16812313 | F20: =Dunelm_Data!F14/Dunelm_Data!F27 -> 0.23200976 | G20: =Dunelm_Data!G14/Dunelm_Data!G27 -> 0.21799656 | H20: =Dunelm_Data!H14/Dunelm_Data!H27 -> 0.22170088 | J20: =Chemring_Data!C13/Chemring_Data!C30 -> 0.064093092 | K20: =Chemring_Data!D13/Chemring_Data!D30 -> 0.078080903 | L20: =Chemring_Data!E13/Chemring_Data!E30 -> 0.076439284 | M20: =Chemring_Data!F13/Chemring_Data!F30 -> 0.009054326 | N20: =Chemring_Data!G13/Chemring_Data!G30 -> 0.057072677 | O20: =Chemring_Data!H13/Chemring_Data!H30 -> 0.055845209 | P20: Both companies maintain positive ROA; Chemring asset-heavy vs Dunelm
A21: Dividend Cover (times) | B21: =eps basic / dps — shows how many times profit covers the dividend | C21: =Dunelm_Data!C15/Dunelm_Data!C55 -> 1.8523985 | D21: =Dunelm_Data!D15/Dunelm_Data!D55 -> 0.82666667 | E21: =Dunelm_Data!E15/Dunelm_Data!E55 -> 5.3083333 | F21: =Dunelm_Data!F15/Dunelm_Data!F55 -> 0.60704023 | G21: =Dunelm_Data!G15/Dunelm_Data!G55 -> 0.93069307 | H21: =Dunelm_Data!H15/Dunelm_Data!H55 -> 0.96015424 | J21: =Chemring_Data!C14/Chemring_Data!C55 -> 3.3243243 | K21: =Chemring_Data!D14/Chemring_Data!D55 -> 3.5 | L21: =Chemring_Data!E14/Chemring_Data!E55 -> 3.0980392 | M21: =Chemring_Data!F14/Chemring_Data!F55 -> 2.1269841 | N21: =Chemring_Data!G14/Chemring_Data!G55 -> 2.1111111 | O21: =Chemring_Data!H14/Chemring_Data!H55 -> 2.4936709 | P21: Dunelm special divs reduce cover FY22; Chemring cover >2x = safe
A22: Dividend Payout Ratio (%) | B22: =dps / eps basic — % of earnings returned as dividend | C22: =Dunelm_Data!C55/Dunelm_Data!C15 -> 0.53984064 | D22: =Dunelm_Data!D55/Dunelm_Data!D15 -> 1.2096774 | E22: =Dunelm_Data!E55/Dunelm_Data!E15 -> 0.18838305 | F22: =Dunelm_Data!F55/Dunelm_Data!F15 -> 1.6473373 | G22: =Dunelm_Data!G55/Dunelm_Data!G15 -> 1.0744681 | H22: =Dunelm_Data!H55/Dunelm_Data!H15 -> 1.0414993 | J22: =Chemring_Data!C55/Chemring_Data!C14 -> 0.30081301 | K22: =Chemring_Data!D55/Chemring_Data!D14 -> 0.28571429 | L22: =Chemring_Data!E55/Chemring_Data!E14 -> 0.32278481 | M22: =Chemring_Data!F55/Chemring_Data!F14 -> 0.47014925 | N22: =Chemring_Data!G55/Chemring_Data!G14 -> 0.47368421 | O22: =Chemring_Data!H55/Chemring_Data!H14 -> 0.40101523 | P22: Dunelm FY22 payout >100% (special dividends funded from cash reserves)
A24: ▸ 2.4 PROFIT QUALITY
A25: Operating Cash Conversion (%) | B25: =net cash from operations / operating profit — tests if EBIT translates to cash | C25: =Dunelm_Data!C39/Dunelm_Data!C9 -> 1.3711584 | D25: =Dunelm_Data!D39/Dunelm_Data!D9 -> 2.1043103 | E25: =Dunelm_Data!E39/Dunelm_Data!E9 -> 1.1069712 | F25: =Dunelm_Data!F39/Dunelm_Data!F9 -> 1.1566376 | G25: =Dunelm_Data!G39/Dunelm_Data!G9 -> 1.2102616 | H25: =Dunelm_Data!H39/Dunelm_Data!H9 -> 1.0890764 | J25: =Chemring_Data!C42/Chemring_Data!C6 -> 1.6393089 | K25: =Chemring_Data!D42/Chemring_Data!D6 -> 1.5019841 | L25: =Chemring_Data!E42/Chemring_Data!E6 -> 1.6295547 | M25: =Chemring_Data!F42/Chemring_Data!F6 -> 1.4515419 | N25: =Chemring_Data!G42/Chemring_Data!G6 -> 1.4310954 | O25: =Chemring_Data!H42/Chemring_Data!H6 -> 1.2411444 | P25: >100% = high quality earnings; both companies typically exceed 100%
A26: Free Cash Flow – FCF (£m) | B26: =net cash from operations + capex (ppe) — note capex is negative in source data | C26: =Dunelm_Data!C39+Dunelm_Data!C42 -> 162 | D26: =Dunelm_Data!D39+Dunelm_Data!D42 -> 223.6 | E26: =Dunelm_Data!E39+Dunelm_Data!E42 -> 169.1 | F26: =Dunelm_Data!F39+Dunelm_Data!F42 -> 228.5 | G26: =Dunelm_Data!G39+Dunelm_Data!G42 -> 219.2 | H26: =Dunelm_Data!H39+Dunelm_Data!H42 -> 202.5 | J26: =Chemring_Data!C42+Chemring_Data!C43 -> 40.3 | K26: =Chemring_Data!D42+Chemring_Data!D43 -> 47.7 | L26: =Chemring_Data!E42+Chemring_Data!E43 -> 49 | M26: =Chemring_Data!F42+Chemring_Data!F43 -> 33.2 | N26: =Chemring_Data!G42+Chemring_Data!G43 -> 18 | O26: =Chemring_Data!H42+Chemring_Data!H43 -> 0.9 | P26: Dunelm FCF very strong; Chemring FCF under pressure from heavy capex FY25
A27: FCF / EBIT Conversion (%) | B27: =free cash flow / operating profit | C27: =(Dunelm_Data!C39+Dunelm_Data!C42)/Dunelm_Data!C9 -> 1.2765957 | D27: =(Dunelm_Data!D39+Dunelm_Data!D42)/Dunelm_Data!D9 -> 1.9275862 | E27: =(Dunelm_Data!E39+Dunelm_Data!E42)/Dunelm_Data!E9 -> 1.016226 | F27: =(Dunelm_Data!F39+Dunelm_Data!F42)/Dunelm_Data!F9 -> 1.0496096 | G27: =(Dunelm_Data!G39+Dunelm_Data!G42)/Dunelm_Data!G9 -> 1.1026157 | H27: =(Dunelm_Data!H39+Dunelm_Data!H42)/Dunelm_Data!H9 -> 0.94936709 | J27: =(Chemring_Data!C42+Chemring_Data!C43)/Chemring_Data!C6 -> 0.87041037 | K27: =(Chemring_Data!D42+Chemring_Data!D43)/Chemring_Data!D6 -> 0.94642857 | L27: =(Chemring_Data!E42+Chemring_Data!E43)/Chemring_Data!E6 -> 0.99190283 | M27: =(Chemring_Data!F42+Chemring_Data!F43)/Chemring_Data!F6 -> 0.73127753 | N27: =(Chemring_Data!G42+Chemring_Data!G43)/Chemring_Data!G6 -> 0.3180212 | O27: =(Chemring_Data!H42+Chemring_Data!H43)/Chemring_Data!H6 -> 0.01226158 | P27: Declining Chemring FCF/EBIT reflects rising defence investment cycle
A29: ▸ 2.5 SUSTAINABILITY OF PROFIT GROWTH
A30: Asset Turnover (x) | B30: =revenue / total assets — efficiency of asset base in generating sales | C30: =Dunelm_Data!C5/Dunelm_Data!C27 -> 2.6382163 | D30: =Dunelm_Data!D5/Dunelm_Data!D27 -> 1.477514 | E30: =Dunelm_Data!E5/Dunelm_Data!E27 -> 1.7427938 | F30: =Dunelm_Data!F5/Dunelm_Data!F27 -> 2.1431088 | G30: =Dunelm_Data!G5/Dunelm_Data!G27 -> 2.3518944 | H30: =Dunelm_Data!H5/Dunelm_Data!H27 -> 2.5021994 | J30: =Chemring_Data!C5/Chemring_Data!C30 -> 0.74344293 | K30: =Chemring_Data!D5/Chemring_Data!D30 -> 0.73998119 | L30: =Chemring_Data!E5/Chemring_Data!E30 -> 0.64666989 | M30: =Chemring_Data!F5/Chemring_Data!F30 -> 0.79242119 | N30: =Chemring_Data!G5/Chemring_Data!G30 -> 0.70553388 | O30: =Chemring_Data!H5/Chemring_Data!H30 -> 0.57641061 | P30: Dunelm ~2.5x excellent; Chemring ~0.6x reflects capital-intensive mfg
A31: Effective Tax Rate (%) | B31: =ABS(taxation) / profit before tax | C31: =ABS(Dunelm_Data!C13)/Dunelm_Data!C12 -> 0.19539317 | D31: =ABS(Dunelm_Data!D13)/Dunelm_Data!D12 -> 0.19615032 | E31: =ABS(Dunelm_Data!E13)/Dunelm_Data!E12 -> 0.18314322 | F31: =ABS(Dunelm_Data!F13)/Dunelm_Data!F12 -> 0.19548872 | G31: =ABS(Dunelm_Data!G13)/Dunelm_Data!G12 -> 0.21172807 | H31: =ABS(Dunelm_Data!H13)/Dunelm_Data!H12 -> 0.26387537 | J31: =ABS(Chemring_Data!C10)/Chemring_Data!C9 -> 0.19861432 | K31: =ABS(Chemring_Data!D10)/Chemring_Data!D9 -> 0.14959016 | L31: =ABS(Chemring_Data!E10)/Chemring_Data!E9 -> 0.073068894 | M31: =ABS(Chemring_Data!F10)/Chemring_Data!F9 -> 0.14512472 | N31: =ABS(Chemring_Data!G10)/Chemring_Data!G9 -> 0.1988417 | O31: =ABS(Chemring_Data!H10)/Chemring_Data!H9 -> 0.2127031 | P31: Dunelm ETR rising to 26.4% FY24; Chemring ETR volatile (deferred tax)
A33: Colour key: Red-shaded = Dunelm data | Green-shaded = Chemring data | Formula column shows Excel logic used for each metric

Sheet 3_Efficiency
A1: EFFICIENCY ANALYSIS
A2: Asset utilisation, inventory management, working capital discipline & operating cycle
A3: Metric | B3: Formula Used | C3: FY2019 | D3: FY2020 | E3: FY2021 | F3: FY2022 | G3: FY2023 | H3: FY2024 | J3: FY2020 | K3: FY2021 | L3: FY2022 | M3: FY2023 | N3: FY2024 | O3: FY2025 | P3: Analyst Notes
B4: ← Formula logic shown here | C4: DUNELM GROUP PLC | J4: CHEMRING GROUP PLC
A5: ▸ 3.1 ASSET USE EFFICIENCY
A6: Asset Turnover (x) | B6: =revenue / total assets — measures how efficiently assets generate sales | C6: =Dunelm_Data!C5/Dunelm_Data!C27 -> 2.6382163 | D6: =Dunelm_Data!D5/Dunelm_Data!D27 -> 1.477514 | E6: =Dunelm_Data!E5/Dunelm_Data!E27 -> 1.7427938 | F6: =Dunelm_Data!F5/Dunelm_Data!F27 -> 2.1431088 | G6: =Dunelm_Data!G5/Dunelm_Data!G27 -> 2.3518944 | H6: =Dunelm_Data!H5/Dunelm_Data!H27 -> 2.5021994 | J6: =Chemring_Data!C5/Chemring_Data!C30 -> 0.74344293 | K6: =Chemring_Data!D5/Chemring_Data!D30 -> 0.73998119 | L6: =Chemring_Data!E5/Chemring_Data!E30 -> 0.64666989 | M6: =Chemring_Data!F5/Chemring_Data!F30 -> 0.79242119 | N6: =Chemring_Data!G5/Chemring_Data!G30 -> 0.70553388 | O6: =Chemring_Data!H5/Chemring_Data!H30 -> 0.57641061 | P6: Dunelm ~2.5x outstanding for retail; Chemring ~0.6x typical for defence mfg
A7: Non-Current Asset Turnover (x) | B7: =revenue / total non-current assets | C7: =Dunelm_Data!C5/Dunelm_Data!C19 -> 5.2474964 | D7: =Dunelm_Data!D5/Dunelm_Data!D19 -> 2.1713875 | E7: =Dunelm_Data!E5/Dunelm_Data!E19 -> 2.9620927 | F7: =Dunelm_Data!F5/Dunelm_Data!F19 -> 3.5875681 | G7: =Dunelm_Data!G5/Dunelm_Data!G19 -> 3.9641993 | H7: =Dunelm_Data!H5/Dunelm_Data!H19 -> 4.1713517 | J7: =Chemring_Data!C5/Chemring_Data!C25 -> 1.0814078 | K7: =Chemring_Data!D5/Chemring_Data!D25 -> 1.0258216 | L7: =Chemring_Data!E5/Chemring_Data!E25 -> 0.91364776 | M7: =Chemring_Data!F5/Chemring_Data!F25 -> 1.1451417 | N7: =Chemring_Data!G5/Chemring_Data!G25 -> 1.156287 | O7: =Chemring_Data!H5/Chemring_Data!H25 -> 0.93638246 | P7: Dunelm NCA inflated post-IFRS16 ROU; Chemring stable capex base
A8: PPE Turnover (x) | B8: =revenue / property, plant & equipment | C8: =Dunelm_Data!C5/Dunelm_Data!C21 -> 6.0930233 | D8: =Dunelm_Data!D5/Dunelm_Data!D21 -> 6.0313569 | E8: =Dunelm_Data!E5/Dunelm_Data!E21 -> 8.2177122 | F8: =Dunelm_Data!F5/Dunelm_Data!F21 -> 9.1042026 | G8: =Dunelm_Data!G5/Dunelm_Data!G21 -> 9.6456739 | H8: =Dunelm_Data!H5/Dunelm_Data!H21 -> 9.8641618 | J8: =Chemring_Data!C5/Chemring_Data!C23 -> 2.0747423 | K8: =Chemring_Data!D5/Chemring_Data!D23 -> 1.9793659 | L8: =Chemring_Data!E5/Chemring_Data!E23 -> 1.7336792 | M8: =Chemring_Data!F5/Chemring_Data!F23 -> 1.9512799 | N8: =Chemring_Data!G5/Chemring_Data!G23 -> 1.6966644 | O8: =Chemring_Data!H5/Chemring_Data!H23 -> 1.4025937 | P8: Dunelm PPE turnover ~6-10x; Chemring ~1.4-2x reflects factory-heavy base
A10: ▸ 3.2 INVENTORY MANAGEMENT
A11: Inventory Days (days) | B11: Dunelm: = Inventory / (CoS / 365) | Chemring: = Inventory / (Revenue / 365) [CoS not disclosed] | C11: =Dunelm_Data!C24/(ABS(Dunelm_Data!C6)/365) -> 103.75 | D11: =Dunelm_Data!D24/(ABS(Dunelm_Data!D6)/365) -> 82.098953 | E11: =Dunelm_Data!E24/(ABS(Dunelm_Data!E6)/365) -> 97.213039 | F11: =Dunelm_Data!F24/(ABS(Dunelm_Data!F6)/365) -> 105.43394 | G11: =Dunelm_Data!G24/(ABS(Dunelm_Data!G6)/365) -> 94.161878 | H11: =Dunelm_Data!H24/(ABS(Dunelm_Data!H6)/365) -> 98.876336 | J11: =Chemring_Data!C26/(Chemring_Data!C5/365) -> 82.793789 | K11: =Chemring_Data!D26/(Chemring_Data!D5/365) -> 74.893211 | L11: =Chemring_Data!E26/(Chemring_Data!E5/365) -> 90.658354 | M11: =Chemring_Data!F26/(Chemring_Data!F5/365) -> 78.545281 | N11: =Chemring_Data!G26/(Chemring_Data!G5/365) -> 95.006144 | O11: =Chemring_Data!H26/(Chemring_Data!H5/365) -> 105.06131 | P11: Dunelm ~100 days seasonal inventory build; Chemring ~75-105 days, rising
A12: Inventory Turnover (x) | B12: Dunelm: = CoS / Inventory | Chemring: = Revenue / Inventory | C12: =ABS(Dunelm_Data!C6)/Dunelm_Data!C24 -> 3.5180723 | D12: =ABS(Dunelm_Data!D6)/Dunelm_Data!D24 -> 4.4458545 | E12: =ABS(Dunelm_Data!E6)/Dunelm_Data!E24 -> 3.7546404 | F12: =ABS(Dunelm_Data!F6)/Dunelm_Data!F24 -> 3.4618834 | G12: =ABS(Dunelm_Data!G6)/Dunelm_Data!G24 -> 3.8763033 | H12: =ABS(Dunelm_Data!H6)/Dunelm_Data!H24 -> 3.6914798 | J12: =Chemring_Data!C5/Chemring_Data!C26 -> 4.4085433 | K12: =Chemring_Data!D5/Chemring_Data!D26 -> 4.8736059 | L12: =Chemring_Data!E5/Chemring_Data!E26 -> 4.0261044 | M12: =Chemring_Data!F5/Chemring_Data!F26 -> 4.647001 | N12: =Chemring_Data!G5/Chemring_Data!G26 -> 3.8418568 | O12: =Chemring_Data!H5/Chemring_Data!H26 -> 3.474162 | P12: Higher is better; Dunelm ~3-5x; Chemring ~3.5-5x
A13: Inventory as % of Revenue | B13: =inventory / revenue — lower = leaner stock management | C13: =Dunelm_Data!C24/Dunelm_Data!C5 -> 0.14331152 | D13: =Dunelm_Data!D24/Dunelm_Data!D5 -> 0.11173079 | E13: =Dunelm_Data!E24/Dunelm_Data!E5 -> 0.1290226 | F13: =Dunelm_Data!F24/Dunelm_Data!F5 -> 0.14101429 | G13: =Dunelm_Data!G24/Dunelm_Data!G5 -> 0.12875275 | H13: =Dunelm_Data!H24/Dunelm_Data!H5 -> 0.13067682 | J13: =Chemring_Data!C26/Chemring_Data!C5 -> 0.2268323 | K13: =Chemring_Data!D26/Chemring_Data!D5 -> 0.20518688 | L13: =Chemring_Data!E26/Chemring_Data!E5 -> 0.24837905 | M13: =Chemring_Data!F26/Chemring_Data!F5 -> 0.21519255 | N13: =Chemring_Data!G26/Chemring_Data!G5 -> 0.2602908 | O13: =Chemring_Data!H26/Chemring_Data!H5 -> 0.2878392 | P13: Both companies show inventory growth above revenue growth in recent years
A15: ▸ 3.3 WORKING CAPITAL DISCIPLINE
A16: Receivable Days / DSO (days) | B16: =trade & other receivables / (revenue / 365) — avg collection period | C16: =Dunelm_Data!C25/(Dunelm_Data!C5/365) -> 8.4914577 | D16: =Dunelm_Data!D25/(Dunelm_Data!D5/365) -> 5.3823613 | E16: =Dunelm_Data!E25/(Dunelm_Data!E5/365) -> 3.2233199 | F16: =Dunelm_Data!F25/(Dunelm_Data!F5/365) -> 5.2855065 | G16: =Dunelm_Data!G25/(Dunelm_Data!G5/365) -> 5.4121918 | H16: =Dunelm_Data!H25/(Dunelm_Data!H5/365) -> 5.6038676 | J16: =Chemring_Data!C27/(Chemring_Data!C5/365) -> 56.949068 | K16: =Chemring_Data!D27/(Chemring_Data!D5/365) -> 56.239512 | L16: =Chemring_Data!E27/(Chemring_Data!E5/365) -> 55.614713 | M16: =Chemring_Data!F27/(Chemring_Data!F5/365) -> 57.769784 | N16: =Chemring_Data!G27/(Chemring_Data!G5/365) -> 68.021708 | O16: =Chemring_Data!H27/(Chemring_Data!H5/365) -> 81.070352 | P16: Dunelm very low DSO (~5-8 days) – cash retail model; Chemring ~50-80 days govt contracts
A17: Payable Days / DPO (days) | B17: Dunelm: = ABS(Trade Payables) / (CoS/365) | Chemring: / (Revenue/365) | C17: =ABS(Dunelm_Data!C29)/(ABS(Dunelm_Data!C6)/365) -> 89.671053 | D17: =ABS(Dunelm_Data!D29)/(ABS(Dunelm_Data!D6)/365) -> 123.07897 | E17: =ABS(Dunelm_Data!E29)/(ABS(Dunelm_Data!E6)/365) -> 102.51352 | F17: =ABS(Dunelm_Data!F29)/(ABS(Dunelm_Data!F6)/365) -> 105.5285 | G17: =ABS(Dunelm_Data!G29)/(ABS(Dunelm_Data!G6)/365) -> 92.86771 | H17: =ABS(Dunelm_Data!H29)/(ABS(Dunelm_Data!H6)/365) -> 90.895287 | J17: =ABS(Chemring_Data!C32)/(Chemring_Data!C5/365) -> 88.144099 | K17: =ABS(Chemring_Data!D32)/(Chemring_Data!D5/365) -> 79.533435 | L17: =ABS(Chemring_Data!E32)/(Chemring_Data!E5/365) -> 89.38404 | M17: =ABS(Chemring_Data!F32)/(Chemring_Data!F5/365) -> 95.768091 | N17: =ABS(Chemring_Data!G32)/(Chemring_Data!G5/365) -> 63.611509 | O17: =ABS(Chemring_Data!H32)/(Chemring_Data!H5/365) -> 72.926633 | P17: Dunelm DPO ~80-95 days – strong supplier leverage; Chemring ~75-95 days
A18: Net Working Capital (£m) | B18: =inventories + trade receivables - trade payables | C18: =Dunelm_Data!C24+Dunelm_Data!C25-ABS(Dunelm_Data!C29) -> 47 | D18: =Dunelm_Data!D24+Dunelm_Data!D25-ABS(Dunelm_Data!D29) -> -43.4 | E18: =Dunelm_Data!E24+Dunelm_Data!E25-ABS(Dunelm_Data!E29) -> 2.4 | F18: =Dunelm_Data!F24+Dunelm_Data!F25-ABS(Dunelm_Data!F29) -> 22.7 | G18: =Dunelm_Data!G24+Dunelm_Data!G25-ABS(Dunelm_Data!G29) -> 27.2 | H18: =Dunelm_Data!H24+Dunelm_Data!H25-ABS(Dunelm_Data!H29) -> 44.2 | J18: =Chemring_Data!C26+Chemring_Data!C27-ABS(Chemring_Data!C32) -> 56.9 | K18: =Chemring_Data!D26+Chemring_Data!D27-ABS(Chemring_Data!D32) -> 55.6 | L18: =Chemring_Data!E26+Chemring_Data!E27-ABS(Chemring_Data!E32) -> 62.5 | M18: =Chemring_Data!F26+Chemring_Data!F27-ABS(Chemring_Data!F32) -> 52.5 | N18: =Chemring_Data!G26+Chemring_Data!G27-ABS(Chemring_Data!G32) -> 133 | O18: =Chemring_Data!H26+Chemring_Data!H27-ABS(Chemring_Data!H32) -> 154.3 | P18: Dunelm NWC often negative (payables > stock+receivables) = excellent WC management
A19: Net Working Capital Days | B19: =net working capital / (revenue / 365) — negative = payables-funded business | C19: =(Dunelm_Data!C24+Dunelm_Data!C25-ABS(Dunelm_Data!C29))/(Dunelm_Data!C5/365) -> 15.589786 | D19: =(Dunelm_Data!D24+Dunelm_Data!D25-ABS(Dunelm_Data!D29))/(Dunelm_Data!D5/365) -> -14.974005 | E19: =(Dunelm_Data!E24+Dunelm_Data!E25-ABS(Dunelm_Data!E29))/(Dunelm_Data!E5/365) -> 0.65559048 | F19: =(Dunelm_Data!F24+Dunelm_Data!F25-ABS(Dunelm_Data!F29))/(Dunelm_Data!F5/365) -> 5.2393449 | G19: =(Dunelm_Data!G24+Dunelm_Data!G25-ABS(Dunelm_Data!G29))/(Dunelm_Data!G5/365) -> 6.0580913 | H19: =(Dunelm_Data!H24+Dunelm_Data!H25-ABS(Dunelm_Data!H29))/(Dunelm_Data!H5/365) -> 9.4538529 | J19: =(Chemring_Data!C26+Chemring_Data!C27-ABS(Chemring_Data!C32))/(Chemring_Data!C5/365) -> 51.598758 | K19: =(Chemring_Data!D26+Chemring_Data!D27-ABS(Chemring_Data!D32))/(Chemring_Data!D5/365) -> 51.599288 | L19: =(Chemring_Data!E26+Chemring_Data!E27-ABS(Chemring_Data!E32))/(Chemring_Data!E5/365) -> 56.889027 | M19: =(Chemring_Data!F26+Chemring_Data!F27-ABS(Chemring_Data!F32))/(Chemring_Data!F5/365) -> 40.546974 | N19: =(Chemring_Data!G26+Chemring_Data!G27-ABS(Chemring_Data!G32))/(Chemring_Data!G5/365) -> 99.416342 | O19: =(Chemring_Data!H26+Chemring_Data!H27-ABS(Chemring_Data!H32))/(Chemring_Data!H5/365) -> 113.20503 | P19: Dunelm negative NWC days = business partly financed by suppliers
A21: ▸ 3.4 OPERATING CYCLE IMPLICATIONS
A22: Cash Conversion Cycle (days) | B22: =dso + dio (inventory days) - dpo — lower/negative = cash generative model | C22: =(Dunelm_Data!C25/(Dunelm_Data!C5/365))+(Dunelm_Data!C24/(ABS(Dunelm_Data!C6)/365))-ABS(Dunelm_Data!C29)/(ABS(Dunelm_Data!C6)/365) -> 22.570405 | D22: =(Dunelm_Data!D25/(Dunelm_Data!D5/365))+(Dunelm_Data!D24/(ABS(Dunelm_Data!D6)/365))-ABS(Dunelm_Data!D29)/(ABS(Dunelm_Data!D6)/365) -> -35.597658 | E22: =(Dunelm_Data!E25/(Dunelm_Data!E5/365))+(Dunelm_Data!E24/(ABS(Dunelm_Data!E6)/365))-ABS(Dunelm_Data!E29)/(ABS(Dunelm_Data!E6)/365) -> -2.0771591 | F22: =(Dunelm_Data!F25/(Dunelm_Data!F5/365))+(Dunelm_Data!F24/(ABS(Dunelm_Data!F6)/365))-ABS(Dunelm_Data!F29)/(ABS(Dunelm_Data!F6)/365) -> 5.1909469 | G22: =(Dunelm_Data!G25/(Dunelm_Data!G5/365))+(Dunelm_Data!G24/(ABS(Dunelm_Data!G6)/365))-ABS(Dunelm_Data!G29)/(ABS(Dunelm_Data!G6)/365) -> 6.7063598 | H22: =(Dunelm_Data!H25/(Dunelm_Data!H5/365))+(Dunelm_Data!H24/(ABS(Dunelm_Data!H6)/365))-ABS(Dunelm_Data!H29)/(ABS(Dunelm_Data!H6)/365) -> 13.584917 | J22: =(Chemring_Data!C27/(Chemring_Data!C5/365))+(Chemring_Data!C26/(Chemring_Data!C5/365))-ABS(Chemring_Data!C32)/(Chemring_Data!C5/365) -> 51.598758 | K22: =(Chemring_Data!D27/(Chemring_Data!D5/365))+(Chemring_Data!D26/(Chemring_Data!D5/365))-ABS(Chemring_Data!D32)/(Chemring_Data!D5/365) -> 51.599288 | L22: =(Chemring_Data!E27/(Chemring_Data!E5/365))+(Chemring_Data!E26/(Chemring_Data!E5/365))-ABS(Chemring_Data!E32)/(Chemring_Data!E5/365) -> 56.889027 | M22: =(Chemring_Data!F27/(Chemring_Data!F5/365))+(Chemring_Data!F26/(Chemring_Data!F5/365))-ABS(Chemring_Data!F32)/(Chemring_Data!F5/365) -> 40.546974 | N22: =(Chemring_Data!G27/(Chemring_Data!G5/365))+(Chemring_Data!G26/(Chemring_Data!G5/365))-ABS(Chemring_Data!G32)/(Chemring_Data!G5/365) -> 99.416342 | O22: =(Chemring_Data!H27/(Chemring_Data!H5/365))+(Chemring_Data!H26/(Chemring_Data!H5/365))-ABS(Chemring_Data!H32)/(Chemring_Data!H5/365) -> 113.20503 | P22: Dunelm CCC often negative – pre-payment retail model; Chemring positive due to contract timings
A23: Revenue per £ of PPE (x) | B23: =revenue / ppe net book value — intensity of fixed assets | C23: =Dunelm_Data!C5/Dunelm_Data!C21 -> 6.0930233 | D23: =Dunelm_Data!D5/Dunelm_Data!D21 -> 6.0313569 | E23: =Dunelm_Data!E5/Dunelm_Data!E21 -> 8.2177122 | F23: =Dunelm_Data!F5/Dunelm_Data!F21 -> 9.1042026 | G23: =Dunelm_Data!G5/Dunelm_Data!G21 -> 9.6456739 | H23: =Dunelm_Data!H5/Dunelm_Data!H21 -> 9.8641618 | J23: =Chemring_Data!C5/Chemring_Data!C23 -> 2.0747423 | K23: =Chemring_Data!D5/Chemring_Data!D23 -> 1.9793659 | L23: =Chemring_Data!E5/Chemring_Data!E23 -> 1.7336792 | M23: =Chemring_Data!F5/Chemring_Data!F23 -> 1.9512799 | N23: =Chemring_Data!G5/Chemring_Data!G23 -> 1.6966644 | O23: =Chemring_Data!H5/Chemring_Data!H23 -> 1.4025937 | P23: Dunelm low fixed asset intensity vs revenue; Chemring capital intensive
A25: Operating cycle analysis: Dunelm's negative CCC is a significant competitive advantage – suppliers effectively fund the business. Chemring's positive CCC reflects defence contract timing.

Sheet 4_Liquidity
A1: LIQUIDITY ANALYSIS
A2: Short-term solvency, working capital sufficiency, cash support for dividends & operational flexibility
A3: Metric | B3: Formula Used | C3: FY2019 | D3: FY2020 | E3: FY2021 | F3: FY2022 | G3: FY2023 | H3: FY2024 | J3: FY2020 | K3: FY2021 | L3: FY2022 | M3: FY2023 | N3: FY2024 | O3: FY2025 | P3: Analyst Notes
B4: ← Formula logic shown here | C4: DUNELM GROUP PLC | J4: CHEMRING GROUP PLC
A5: ▸ 4.1 SHORT-TERM SOLVENCY
A6: Current Ratio (x) | B6: =total current assets / ABS(total current liabilities) — benchmark: >1.5x comfortable | C6: =Dunelm_Data!C23/ABS(Dunelm_Data!C28) -> 1.3845127 | D6: =Dunelm_Data!D23/ABS(Dunelm_Data!D28) -> 1.0043898 | E6: =Dunelm_Data!E23/ABS(Dunelm_Data!E28) -> 1.337855 | F6: =Dunelm_Data!F23/ABS(Dunelm_Data!F28) -> 1.0764493 | G6: =Dunelm_Data!G23/ABS(Dunelm_Data!G28) -> 1.0511869 | H6: =Dunelm_Data!H23/ABS(Dunelm_Data!H28) -> 1.0356736 | J6: =Chemring_Data!C29/ABS(Chemring_Data!C33) -> 1.5134168 | K6: =Chemring_Data!D29/ABS(Chemring_Data!D33) -> 1.444878 | L6: =Chemring_Data!E29/ABS(Chemring_Data!E33) -> 1.5936675 | M6: =Chemring_Data!F29/ABS(Chemring_Data!F33) -> 1.2927516 | N6: =Chemring_Data!G29/ABS(Chemring_Data!G33) -> 1.5502055 | O6: =Chemring_Data!H29/ABS(Chemring_Data!H33) -> 1.5963257 | P6: Dunelm ~1.0-1.3x; adequate for cash-generative retail. Chemring typically >1.2x
A7: Quick Ratio / Acid Test (x) | B7: =(total current assets - inventories) / ABS(current liabilities) — benchmark: >1.0x | C7: =(Dunelm_Data!C23-Dunelm_Data!C24)/ABS(Dunelm_Data!C28) -> 0.3317757 | D7: =(Dunelm_Data!D23-Dunelm_Data!D24)/ABS(Dunelm_Data!D28) -> 0.48551361 | E7: =(Dunelm_Data!E23-Dunelm_Data!E24)/ABS(Dunelm_Data!E28) -> 0.60703688 | F7: =(Dunelm_Data!F23-Dunelm_Data!F24)/ABS(Dunelm_Data!F28) -> 0.26847826 | G7: =(Dunelm_Data!G23-Dunelm_Data!G24)/ABS(Dunelm_Data!G28) -> 0.26854599 | H7: =(Dunelm_Data!H23-Dunelm_Data!H24)/ABS(Dunelm_Data!H28) -> 0.18937381 | J7: =(Chemring_Data!C29-Chemring_Data!C26)/ABS(Chemring_Data!C33) -> 0.69677996 | K7: =(Chemring_Data!D29-Chemring_Data!D26)/ABS(Chemring_Data!D33) -> 0.65756098 | L7: =(Chemring_Data!E29-Chemring_Data!E26)/ABS(Chemring_Data!E33) -> 0.7176781 | M7: =(Chemring_Data!F29-Chemring_Data!F26)/ABS(Chemring_Data!F33) -> 0.57705841 | N7: =(Chemring_Data!G29-Chemring_Data!G26)/ABS(Chemring_Data!G33) -> 0.80387551 | O7: =(Chemring_Data!H29-Chemring_Data!H26)/ABS(Chemring_Data!H33) -> 0.88530288 | P7: Dunelm quick ratio ~0.3-0.5x; low but supported by strong operating cash flow
A8: Cash Ratio (x) | B8: =cash & equivalents / ABS(current liabilities) | C8: =Dunelm_Data!C26/ABS(Dunelm_Data!C28) -> 0.12683578 | D8: =Dunelm_Data!D26/ABS(Dunelm_Data!D28) -> 0.39508341 | E8: =Dunelm_Data!E26/ABS(Dunelm_Data!E28) -> 0.54514625 | F8: =Dunelm_Data!F26/ABS(Dunelm_Data!F28) -> 0.10942029 | G8: =Dunelm_Data!G26/ABS(Dunelm_Data!G28) -> 0.17173591 | H8: =Dunelm_Data!H26/ABS(Dunelm_Data!H28) -> 0.088804554 | J8: =Chemring_Data!C28/ABS(Chemring_Data!C33) -> 0.13148479 | K8: =Chemring_Data!D28/ABS(Chemring_Data!D33) -> 0.056585366 | L8: =Chemring_Data!E28/ABS(Chemring_Data!E33) -> 0.17414248 | M8: =Chemring_Data!F28/ABS(Chemring_Data!F33) -> 0.045038705 | N8: =Chemring_Data!G28/ABS(Chemring_Data!G33) -> 0.26423958 | O8: =Chemring_Data!H28/ABS(Chemring_Data!H33) -> 0.32423039 | P8: Dunelm cash ratio very low FY24; managed via RCF facility headroom
A10: ▸ 4.2 WORKING CAPITAL SUFFICIENCY
